Workbook

Sheet RESUMEN
A1: FEBRERO
B2: GASTOS | C2: 27070.25
B3: OTROS GASTOS | C3: 4290.86
B4: DEUDORES | C4: 22455.65
B5: SALDO ANTERIOR | C5: 46336 | D5: SALDO
B6: DISPONIBILIDAD | C6: 19589.49 | D6: =+C6 -> 19589.49
A8: MARZO
B9: GASTOS | C9: =60000-12303.14 -> 47696.86
B10: OTROS GASTOS | C10: 3300.57
B11: DEUDORES | C11: 16994.7
B12: SALDO ANTERIOR | C12: 46336
B13: DISPONIBIILDAD | C13: 26040.73 | D13: SALDO
B14: F.F. | C14: 10000 | D14: =+C13+C14 -> 36040.73
A16: ABRIL
B17: GASTOS | C17: =60000-15609.35 -> 44390.65
B18: OTROS GASTOS | C18: 3939.82
B19: DEUDORES | C19: 33249.49
B20: SALDO ANTERIOR | C20: 46336
B21: DISPONIBILIDAD | C21: 9146.69 | D21: SALDO
B22: F.F. | C22: 22303.14 | D22: =+C22+C21 -> 31449.83
A24: MAYO
B25: GASTOS | C25: =60000-5958.81 -> 54041.19
B26: OTROS GASTOS | C26: 8064.52
B27: DEUDORES | C27: 21909.91
B28: SALDO ANTERIOR | C28: 46336
B29: DISPONIBILIDAD | C29: 16361.57 | D29: SALDO
B30: F.F. | C30: 37912.49 | D30: =+C30+C29 -> 54274.06
A32: JUNIO
B33: GASTOS | C33: 49440.97
B34: OTROS GASTOS | C34: 4892.52
B35: DEUDORES | C35: 21570.39
B36: SALDO ANTERIOR | C36: 46336
B37: DISPONIBILIDAD | C37: =+C36-C34-C35 -> 19873.09 | D37: SALDO
B38: F.F. | C38: 43871.3 | D38: =+C37+C38 -> 63744.39
A40: JULIO
B41: GASTOS | C41: 45868.57
B42: OTROS GASTOS | C42: 3804.12
B43: DEUDORES | C43: 20222.26
B44: SALDO ANTERIOR | C44: 46336
B45: DISPONIBILIDAD | C45: =+C44-C42-C43 -> 22309.62 | D45: SALDO
...

Sheet detalle expensas
A1: CONCEPTO | B1: ENERO | C1: FEBRERO | D1: MARZO | E1: ABRIL | F1: MAYO | G1: JUNIO | H1: JULIO | I1: AGOSTO | J1: SEPTIEMBRE
B2: feb | C2: mar | D2: abr | E2: may | F2: jun | G2: jul | H2: agos | I2: sept
A3: Total de gastos | B3: =SUM(B6:B44) -> 59281.04 | C3: =SUM(C6:C44) -> 27070.25 | D3: =SUM(D7:D44) -> 47696.86 | E3: =SUM(E6:E44) -> 44390.65 | F3: =SUM(F6:F44) -> 54041.19 | G3: =SUM(G6:G44) -> 49440.97 | H3: =SUM(H6:H44) -> 45868.57 | I3: =SUM(I6:I44) -> 66083.37 | J3: =SUM(J6:J44) -> 0
A4: FONDO FIJO - Saldo pactado | C4: 10000 | D4: =60000-D3 -> 12303.14 | E4: =60000-E3 -> 15609.35 | F4: =60000-F3 -> 5958.81 | G4: =60000-G3 -> 10559.03 | H4: =60000-H3 -> 14131.43 | I4: =60000-I3 -> -6083.37 | J4: =60000-J3 -> 60000
A6: Gastos Mensuales FIJOS
A7: SERVICIO DE LIMPIEZA | B7: 7000 | C7: 7000 | D7: 7000 | E7: 7000 | F7: 3966.67
A8: JUANORAMA - Serv Limpieza | F8: 9750 | G8: 19500 | H8: 19500 | I8: 19500
A9: CONVER - SERVICE ASCENSOR | B9: 7440 | C9: 7440 | D9: 7440 | E9: 7440 | F9: =8950+1510 -> 10460 | G9: 8950 | H9: 8950 | I9: 8950
A10: LA SEGUNDA - SEGURO EDIFICIO | B10: =1740+1740 -> 3480 | C10: 1740 | D10: 1740 | E10: 1740 | F10: 1740 | G10: 1740 | H10: 1740 | I10: 1740
A11: LA SEGUNDA - ACC. PERSONALES | B11: 358 | C11: 358 | D11: 358 | E11: 358 | F11: 358 | G11: 358 | H11: 358
A12: GASTOS BANCARIOS | C12: 3072.86 | D12: 1731.39 | E12: 1841.82 | F12: 1894.59 | G12: 2034.52 | H12: 1706.12 | I12: 1676.88
A13: E.P.E. - | B13: 4457.74 | C13: 3741.39 | D13: 3766.29 | E13: 3810.83 | F13: 4071.93 | G13: 2214.45 | H13: 2214.45 | I13: 2214.45
A14: SBARRA - AYUDA VECINAL | D14: =1300+1300 -> 2600 | E14: 1300 | F14: 1300 | G14: 1300 | H14: 1300 | I14: 1300
A15: HONORARIOS ADMNISTRACION | D15: =9500+9500 -> 19000 | E15: 9500 | F15: 9500 | G15: 9500 | H15: 9500 | I15: 9500
A16: COMISION Bco ROELA | I16: =2653.43+2252.61 -> 4906.04
A20: Gastos Varios Extraordinarios
A21: AFIP - plan pagos | B21: 2500 | C21: 2500 | D21: 2500 | E21: 2500 | F21: 2500
A22: LA RAPIDA - NO LIQUIDADO Adm anterior | B22: 3993
A23: LA RAPIDA - NO LIQUIDADO Adm anterior | B23: 24962.3
A24: HONORARIOS ABOGADA (envio CD) | B24: 4000
A25: CERRAJERIA | B25: 360 | C25: 840
A26: FOTOCOPIAS | B26: 730 | C26: 378 | D26: 320 | I26: 466
A27: ART LIMPIEZA - LA GALLEGA | D27: 441.18
A28: ELECTRO A - REVISION LUCES | D28: 450 | G28: 2644
A29: LIBRERÍA - | D29: 350
A30: NOPLAX - Limpieza de Tanques | E30: 8900
A31: HERNAN ROMANO - Limpieza Caños Desagüe sector C | F31: 8500 | I31: 4500
A32: Reparacion Cerradura INGRESO | G32: 1200 | H32: 600
A33: LA RAPIDA - destape PB C | I33: 6050
A34: LA RAPIDA - destape 4B | I34: 5280

Sheet CAJA(según planillas)
A1: FECHA / MES | B1: DETALLE DE CAJA | C1: INGRESOS | D1: SALIDAS | E1: DEUDORES | F1: SALDO | H1: =SUM(H3:H60) -> 68561.76 | I1: FONDO FIJO
A3: 43895 | B3: Saldo Bancario al 28/Enero - Adm Anterior | C3: 41127 | F3: =+F2+C3-D3 -> 41127
B4: Exp. Aduedadas Admin Anterior 03-04 | C4: 940 | F4: =+F3+C4-D4 -> 42067
B5: Exp. Aduedadas Admin Anterior 05-02 | C5: 1355 | F5: =+F4+C5-D5 -> 43422
B6: Exp. Aduedadas Admin Anterior 06-04 | C6: 1974 | F6: =+F5+C6-D6 -> 45396
B7: Exp. Aduedadas Admin Anterior 07-04 | C7: 940 | F7: =+F6+C7-D7 -> 46336
B8: GASTOS ENERO | D8: 59281.04 | F8: =+F7+C8-D8 -> -12945.04
B9: GASTOS FEBRERO | D9: 27070.25 | F9: =+F8+C9-D9 -> -40015.29
B10: FONDO FIJO FEBRERO | D10: =+H10 -> 10000 | F10: =+F9+C10-D10 -> -50015.29 | H10: 10000
B11: COBRO EXPENSAS ENERO (AL 28-02) | C11: =+DEUDORES!E4 -> 36825.382 | F11: =+F10+C11-D11 -> -13189.908
B12: COBRO EXPENSAS FEBRERO (AL 31-03) | C12: =+DEUDORES!G4 -> 26620.147 | F12: =+F11+C12-D12 -> 13430.239
B13: COBRO DEUDORES ATRASADOS | C13: =+DEUDORES!H3 -> 15911.031 | F13: =+F12+C13-D13 -> 29341.27
B14: Exp. Aduedadas Admin Anterior 01-02 | C14: =+DEUDORES!D11 -> 1354 | F14: =+F13+C14-D14 -> 30695.27
B15: Exp. Aduedadas Admin Anterior 03-01 | C15: =+DEUDORES!D18 -> 10310 | F15: =+F14+C15-D15 -> 41005.27
B16: Exp. Aduedadas Admin Anterior 05-03 | C16: =+DEUDORES!D28 -> 1170 | F16: =+F15+C16-D16 -> 42175.27
A17: 43921 | B17: DEUDORES AL 31-03 | E17: =+DEUDORES!H4 -> 16994.73 | F17: =+F16+C17-D17 -> 42175.27
F18: =+F17+C18-D18 -> 42175.27
B19: GASTOS MARZO | D19: 47696.86 | F19: =+F18+C19-D19 -> -5521.5903
B20: FONDO FIJO MARZO | D20: 12303.14 | F20: =+F19+C20-D20 -> -17824.73 | H20: 12303.14
B21: COBRO EXPENSAS MARZO (al 30-04) | C21: =+DEUDORES!I4 -> 39990 | F21: =+F20+C21-D21 -> 22165.27
B22: COBRO DEUDORES ATRASADOS | C22: =+DEUDORES!J3 -> 4919.2222 | F22: =+F21+C22-D22 -> 27084.492
A23: 43951 | B23: DEUDORES AL 30-4 | E23: =+DEUDORES!J4 -> 33249.498 | F23: =+F22+C23-D23 -> 27084.492
F24: =+F23+C24-D24 -> 27084.492
B25: GASTOS ABRIL | D25: 44390.65 | F25: =+F24+C25-D25 -> -17306.158
B26: FONDO FIJO ABRIL | D26: 15609.35 | F26: =+F25+C26-D26 -> -32915.508 | H26: 15609.35
B27: COBRO EXPENSAS ABRIL (AL 31-05) | C27: =+DEUDORES!K4 -> 52854 | F27: =+F26+C27-D27 -> 19938.492
B28: COBRO DEUDORES ATRASADOS | C28: =+DEUDORES!L3 -> 18485.583 | F28: =+F27+C28-D28 -> 38424.075
B29: Exp. Aduedadas Admin Anterior 04-01 | C29: 1355 | F29: =+F28+C29-D29 -> 39779.075
B30: Exp. Aduedadas Admin Anterior 09-04 | C30: 940 | F30: =+F29+C30-D30 -> 40719.075
B31: Exp. Aduedadas Admin Anterior Extraord 03-04 | C31: 2700 | F31: =+F30+C31-D31 -> 43419.075
A32: 43982 | B32: DEUDORES AL 31-05 | E32: =+DEUDORES!L4 -> 21909.915 | F32: =+F31+C32-D32 -> 43419.075
F33: =+F32+C33-D33 -> 43419.075
B34: GASTOS MAYO | D34: 54041.19 | F34: =+F33+C34-D34 -> -10622.115
B35: FONDO FIJO MAYO | D35: 5958.81 | F35: =+F34+C35-D35 -> -16580.925 | H35: 5958.81
B36: COBRO EXPENSAS MAYO (AL 30-06) | C36: =+DEUDORES!M4 -> 49974 | F36: =+F35+C36-D36 -> 33393.075
B37: COBRO DEUDORES ATRASADOS | C37: =+DEUDORES!N3 -> 9201.5209 | F37: =+F36+C37-D37 -> 42594.596
B38: Exp. Aduedadas Admin Anterior 08-01 | C38: 2845 | F38: =+F37+C38-D38 -> 45439.596
B39: Exp. Aduedadas Admin Anterior Extraord 08-01 | C39: 3800 | F39: =+F38+C39-D39 -> 49239.596
A40: 44012 | B40: DEUDORES AL 30-06 | E40: =+DEUDORES!N4 -> 21570.394 | F40: =+F39+C40-D40 -> 49239.596
F41: =+F40+C41-D41 -> 49239.596
...

Sheet DEUDORES
B1: UNIDAD | C1: % | E1: ENERO | F1: AL 05-03 | G1: FEBRERO | H1: AL 31-03 | I1: MARZO | J1: AL 30-04 | K1: ABRIL | L1: AL 31-05 | M1: MAYO | N1: AL 30-06 | O1: JUNIO | P1: AL 31-07 | Q1: JULIO | R1: AL 31-8 | S1: AGOSTO
D2: DEUDA ANTERIOR | E2: 59281.04 | F2: Deuda | G2: 37070.25 | H2: Deuda | I2: 60000 | J2: Deuda | K2: 60000 | L2: Deuda | M2: 60000 | N2: Deuda | O2: 60000 | P2: Deuda | Q2: 60000 | R2: Deuda | S2: 66083.37 | T2: Deuda
B3: COBRADO Deuda | H3: =+F7+F18+F20+F22+F23+F31+F34+F35+F37+F41 -> 15911.031 | J3: =+H18+H20+H27+H30+H40 -> 4919.2222 | L3: =+J7+J13+J21+J22+J25+J28+J30+J37+J41+J45 -> 18485.583 | N3: =+F38+L6+L23 -> 9201.5209 | P3: =+N12+N29+N33+N41 -> 13282.134 | R3: =+P21+P23+P27+P33+P38+P41 -> 15758.26
B4: COBRADO MES | E4: =+E8+E9+E10+E11+E13+E14+E15+E16+E17+E19+E21+E24+E26+E27+E28+E30+E29+E32+E33+E36+E39+E40+E42+E43+E44 -> 36825.382 | F4: =SUM(F6:F46) -> 22455.658 | G4: =+G7+G8+G9+G10+G11+G13+G14+G15+G16+G17+G19+G22+G23+G24+G26+G28+G31+G32+G33+G34+G35+G36+G37+G39+G41+G42+G43+G44 -> 26620.147 | H4: =SUM(H6:H46) -> 16994.73 | I4: =+I8+I9+I10+I11+I14+I15+I16+I17+I18+I19+I20+I24+I26+I27+I29+I31+I32+I33+I34+I35+I36+I39+I40+I42+I43+I44 -> 39990 | J4: =SUM(J6:J46) -> 33249.498 | K4: =+K7+K8+K9+K10+K11+K13+K14+K15+K16+K17+K18+K19+K20+K21+K22+K24+K25+K26+K27+K28+K30+K31+K32+K33+K34+K35+K36+K37+K39+K40+K41+K42+K43+K44+K45 -> 52854 | L4: =SUM(L6:L46) -> 21909.915 | M4: =+M6+M8+M9+M10+M11+M13+M14+M15+M16+M17+M18+M19+M20+M22+M23+M24+M25+M26+M27+M28+M30+M31+M32+M34+M35+M36+M37+M39+M40+M42+M43+M44+M45 -> 49974 | N4: =SUM(N6:N46) -> 21570.394 | O4: =+O6+O8+O9+O10+O11+O12+O13+O14+O15+O16+O17+O18+O19+O20+O22+O24+O25+O26+O28+O29+O30+O31+O32+O34+O35+O36+O37+O39+O40+O42+O43+O44+O45 -> 49230 | P4: =SUM(P6:P46) -> 20222.26 | Q4: =+Q6+Q8+Q9+Q10+Q11+Q12+Q13+Q14+Q15+Q16+Q18+Q20+Q21+Q22+Q23+Q24+Q25+Q26+Q27+Q28+Q29+Q30+Q31+Q32+Q33+Q34+Q35+Q36+Q37+Q38+Q39+Q40+Q41+Q42+Q43+Q44+Q45 -> 54918 | R4: =SUM(R6:R46) -> 9546 | S4: =+S2-T4 -> 66083.37 | T4: =SUM(T6:T46) -> 0
A6: 1 | B6: 00-01 | C6: 0.0193 | E6: =+$E$2*C6 -> 1144.1241 | F6: =+E6 -> 1144.1241 | G6: =+$G$2*C6 -> 715.45583 | H6: =+G6+F6 -> 1859.5799 | I6: =+$I$2*C6 -> 1158 | J6: =+H6+I6 -> 3017.5799 | K6: =+$K$2*$C6 -> 1158 | L6: =+K6+J6 -> 4175.5799 | M6: =+$M$2*$C6 -> 1158 | O6: =+$O$2*$C6 -> 1158 | Q6: =+$Q$2*$C6 -> 1158 | S6: =+$S$2*$C6 -> 1275.409
A7: 2 | B7: 00-02 | C7: 0.0372 | E7: =+$E$2*C7 -> 2205.2547 | F7: =+E7 -> 2205.2547 | G7: =+$G$2*C7 -> 1379.0133 | I7: =+$I$2*C7 -> 2232 | J7: =+I7 -> 2232 | K7: =+$K$2*$C7 -> 2232 | M7: =+$M$2*$C7 -> 2232 | N7: =+M7 -> 2232 | O7: =+$O$2*$C7 -> 2232 | P7: =+O7+N7 -> 4464 | Q7: =+$Q$2*$C7 -> 2232 | R7: =+Q7+P7 -> 6696 | S7: =+$S$2*$C7 -> 2458.3014
A8: 3 | B8: 00-03 | C8: 0.0255 | E8: =+$E$2*C8 -> 1511.6665 | G8: =+$G$2*C8 -> 945.29137 | I8: =+$I$2*C8 -> 1530 | K8: =+$K$2*$C8 -> 1530 | M8: =+$M$2*$C8 -> 1530 | O8: =+$O$2*$C8 -> 1530 | Q8: =+$Q$2*$C8 -> 1530 | S8: =+$S$2*$C8 -> 1685.1259
A9: 4 | B9: 00-04 | C9: 0.0198 | E9: =+$E$2*C9 -> 1173.7646 | G9: =+$G$2*C9 -> 733.99095 | I9: =+$I$2*C9 -> 1188 | K9: =+$K$2*$C9 -> 1188 | M9: =+$M$2*$C9 -> 1188 | O9: =+$O$2*$C9 -> 1188 | Q9: =+$Q$2*$C9 -> 1188 | S9: =+$S$2*$C9 -> 1308.4507
A10: 5 | B10: 101 | C10: 0.0279 | E10: =+$E$2*C10 -> 1653.941 | G10: =+$G$2*C10 -> 1034.26 | I10: =+$I$2*C10 -> 1674 | K10: =+$K$2*$C10 -> 1674 | M10: =+$M$2*$C10 -> 1674 | O10: =+$O$2*$C10 -> 1674 | Q10: =+$Q$2*$C10 -> 1674 | S10: =+$S$2*$C10 -> 1843.726
A11: 6 | B11: 102 | C11: 0.0281 | D11: 1354 | E11: =+$E$2*C11 -> 1665.7972 | G11: =+$G$2*C11 -> 1041.674 | I11: =+$I$2*C11 -> 1686 | K11: =+$K$2*$C11 -> 1686 | M11: =+$M$2*$C11 -> 1686 | O11: =+$O$2*$C11 -> 1686 | Q11: =+$Q$2*$C11 -> 1686 | S11: =+$S$2*$C11 -> 1856.9427
A12: 7 | B12: 103 | C12: 0.0244 | E12: =+$E$2*C12 -> 1446.4574 | F12: =+E12 -> 1446.4574 | G12: =+$G$2*C12 -> 904.5141 | H12: =+G12+F12 -> 2350.9715 | I12: =+$I$2*C12 -> 1464 | J12: =+H12+I12 -> 3814.9715 | K12: =+$K$2*$C12 -> 1464 | L12: =+K12+J12 -> 5278.9715 | M12: =+$M$2*$C12 -> 1464 | N12: =+L12+M12 -> 6742.9715 | O12: =+$O$2*$C12 -> 1464 | Q12: =+$Q$2*$C12 -> 1464 | S12: =+$S$2*$C12 -> 1612.4342
A13: 8 | B13: 104 | C13: 0.0194 | E13: =+$E$2*C13 -> 1150.0522 | G13: =+$G$2*C13 -> 719.16285 | I13: =+$I$2*C13 -> 1164 | J13: =+I13 -> 1164 | K13: =+$K$2*$C13 -> 1164 | M13: =+$M$2*$C13 -> 1164 | O13: =+$O$2*$C13 -> 1164 | Q13: =+$Q$2*$C13 -> 1164 | S13: =+$S$2*$C13 -> 1282.0174
A14: 9 | B14: 201 | C14: 0.0279 | E14: =+$E$2*C14 -> 1653.941 | G14: =+$G$2*C14 -> 1034.26 | I14: =+$I$2*C14 -> 1674 | K14: =+$K$2*$C14 -> 1674 | M14: =+$M$2*$C14 -> 1674 | O14: =+$O$2*$C14 -> 1674 | Q14: =+$Q$2*$C14 -> 1674 | S14: =+$S$2*$C14 -> 1843.726
A15: 10 | B15: 202 | C15: 0.0281 | E15: =+$E$2*C15 -> 1665.7972 | G15: =+$G$2*C15 -> 1041.674 | I15: =+$I$2*C15 -> 1686 | K15: =+$K$2*$C15 -> 1686 | M15: =+$M$2*$C15 -> 1686 | O15: =+$O$2*$C15 -> 1686 | Q15: =+$Q$2*$C15 -> 1686 | S15: =+$S$2*$C15 -> 1856.9427
A16: 11 | B16: 203 | C16: 0.0244 | E16: =+$E$2*C16 -> 1446.4574 | G16: =+$G$2*C16 -> 904.5141 | I16: =+$I$2*C16 -> 1464 | K16: =+$K$2*$C16 -> 1464 | M16: =+$M$2*$C16 -> 1464 | O16: =+$O$2*$C16 -> 1464 | Q16: =+$Q$2*$C16 -> 1464 | S16: =+$S$2*$C16 -> 1612.4342
A17: 12 | B17: 204 | C17: 0.0194 | E17: =+$E$2*C17 -> 1150.0522 | G17: =+$G$2*C17 -> 719.16285 | I17: =+$I$2*C17 -> 1164 | K17: =+$K$2*$C17 -> 1164 | M17: =+$M$2*$C17 -> 1164 | O17: =+$O$2*$C17 -> 1164 | Q17: =+$Q$2*$C17 -> 1164 | R17: =+Q17 -> 1164 | S17: =+$S$2*$C17 -> 1282.0174
A18: 13 | B18: 301 | C18: 0.0279 | D18: 10310 | E18: =+$E$2*C18 -> 1653.941 | F18: =+E18 -> 1653.941 | G18: =+$G$2*C18 -> 1034.26 | H18: =+G18 -> 1034.26 | I18: =+$I$2*C18 -> 1674 | K18: =+$K$2*$C18 -> 1674 | M18: =+$M$2*$C18 -> 1674 | O18: =+$O$2*$C18 -> 1674 | Q18: =+$Q$2*$C18 -> 1674 | S18: =+$S$2*$C18 -> 1843.726
A19: 14 | B19: 302 | C19: 0.0281 | E19: =+$E$2*C19 -> 1665.7972 | G19: =+$G$2*C19 -> 1041.674 | I19: =+$I$2*C19 -> 1686 | K19: =+$K$2*$C19 -> 1686 | M19: =+$M$2*$C19 -> 1686 | O19: =+$O$2*$C19 -> 1686 | Q19: =+$Q$2*$C19 -> 1686 | R19: =+Q19 -> 1686 | S19: =+$S$2*$C19 -> 1856.9427
A20: 15 | B20: 303 | C20: 0.0244 | E20: =+$E$2*C20 -> 1446.4574 | F20: =+E20 -> 1446.4574 | G20: =+$G$2*C20 -> 904.5141 | H20: =+G20 -> 904.5141 | I20: =+$I$2*C20 -> 1464 | K20: =+$K$2*$C20 -> 1464 | M20: =+$M$2*$C20 -> 1464 | O20: =+$O$2*$C20 -> 1464 | Q20: =+$Q$2*$C20 -> 1464 | S20: =+$S$2*$C20 -> 1612.4342
A21: 16 | B21: 304 | C21: 0.0194 | D21: 940 | E21: =+$E$2*C21 -> 1150.0522 | G21: =+$G$2*C21 -> 719.16285 | H21: =+G21 -> 719.16285 | I21: =+$I$2*C21 -> 1164 | J21: =+I21+H21 -> 1883.1629 | K21: =+$K$2*$C21 -> 1164 | M21: =+$M$2*$C21 -> 1164 | O21: =+$O$2*$C21 -> 1164 | P21: =+O21+M21 -> 2328 | Q21: =+$Q$2*$C21 -> 1164 | S21: =+$S$2*$C21 -> 1282.0174
A22: 17 | B22: 401 | C22: 0.0279 | D22: 1355 | E22: =+$E$2*C22 -> 1653.941 | F22: =+E22 -> 1653.941 | G22: =+$G$2*C22 -> 1034.26 | I22: =+$I$2*C22 -> 1674 | J22: =+I22 -> 1674 | K22: =+$K$2*$C22 -> 1674 | M22: =+$M$2*$C22 -> 1674 | O22: =+$O$2*$C22 -> 1674 | Q22: =+$Q$2*$C22 -> 1674 | S22: =+$S$2*$C22 -> 1843.726
A23: 18 | B23: 402 | C23: 0.0281 | E23: =+$E$2*C23 -> 1665.7972 | F23: =+E23 -> 1665.7972 | G23: =+$G$2*C23 -> 1041.674 | I23: =+$I$2*C23 -> 1686 | J23: =+I23 -> 1686 | K23: =+$K$2*$C23 -> 1686 | L23: =+K23+J23 -> 3372 | M23: =+$M$2*$C23 -> 1686 | O23: =+$O$2*$C23 -> 1686 | P23: =+O23 -> 1686 | Q23: =+$Q$2*$C23 -> 1686 | S23: =+$S$2*$C23 -> 1856.9427
A24: 19 | B24: 403 | C24: 0.0244 | E24: =+$E$2*C24 -> 1446.4574 | G24: =+$G$2*C24 -> 904.5141 | I24: =+$I$2*C24 -> 1464 | K24: =+$K$2*$C24 -> 1464 | M24: =+$M$2*$C24 -> 1464 | O24: =+$O$2*$C24 -> 1464 | Q24: =+$Q$2*$C24 -> 1464 | S24: =+$S$2*$C24 -> 1612.4342
A25: 20 | B25: 404 | C25: 0.0194 | D25: 17688 | E25: =+$E$2*C25 -> 1150.0522 | F25: =+E25 -> 1150.0522 | G25: =+$G$2*C25 -> 719.16285 | H25: =+G25+F25 -> 1869.215 | I25: =+$I$2*C25 -> 1164 | J25: =+H25+I25-0.01 -> 3033.205 | K25: =+$K$2*$C25 -> 1164 | M25: =+$M$2*$C25 -> 1164 | O25: =+$O$2*$C25 -> 1164 | Q25: =+$Q$2*$C25 -> 1164 | S25: =+$S$2*$C25 -> 1282.0174
A26: 21 | B26: 501 | C26: 0.0279 | E26: =+$E$2*C26 -> 1653.941 | G26: =+$G$2*C26 -> 1034.26 | I26: =+$I$2*C26 -> 1674 | K26: =+$K$2*$C26 -> 1674 | M26: =+$M$2*$C26 -> 1674 | O26: =+$O$2*$C26 -> 1674 | Q26: =+$Q$2*$C26 -> 1674 | S26: =+$S$2*$C26 -> 1843.726
A27: 22 | B27: 502 | C27: 0.0281 | D27: 1355 | E27: =+$E$2*C27 -> 1665.7972 | G27: =+$G$2*C27 -> 1041.674 | H27: =+G27 -> 1041.674 | I27: =+$I$2*C27 -> 1686 | K27: =+$K$2*$C27 -> 1686 | M27: =+$M$2*$C27 -> 1686 | O27: =+$O$2*$C27 -> 1686 | P27: =+O27 -> 1686 | Q27: =+$Q$2*$C27 -> 1686 | S27: =+$S$2*$C27 -> 1856.9427
A28: 23 | B28: 503 | C28: 0.0244 | D28: 1170 | E28: =+$E$2*C28 -> 1446.4574 | G28: =+$G$2*C28 -> 904.5141 | I28: =+$I$2*C28 -> 1464 | J28: =+I28 -> 1464 | K28: =+$K$2*$C28 -> 1464 | M28: =+$M$2*$C28 -> 1464 | O28: =+$O$2*$C28 -> 1464 | Q28: =+$Q$2*$C28 -> 1464 | S28: =+$S$2*$C28 -> 1612.4342
A29: 24 | B29: 504 | C29: 0.0194 | E29: =+$E$2*C29 -> 1150.0522 | G29: =+$G$2*C29 -> 719.16285 | H29: =+G29 -> 719.16285 | I29: =+$I$2*C29 -> 1164 | J29: =+I29+H29 -> 1883.1629 | K29: =+$K$2*$C29 -> 1164 | L29: =+K29+J29 -> 3047.1629 | M29: =+$M$2*$C29 -> 1164 | N29: =+M29+L29 -> 4211.1629 | O29: =+$O$2*$C29 -> 1164 | Q29: =+$Q$2*$C29 -> 1164 | S29: =+$S$2*$C29 -> 1282.0174
A30: 25 | B30: 601 | C30: 0.0279 | D30: 36764 | E30: =+$E$2*C30 -> 1653.941 | G30: =+$G$2*C30 -> 1034.26 | H30: =+G30 -> 1034.26 | I30: =+$I$2*C30 -> 1674 | J30: =+I30 -> 1674 | K30: =+$K$2*$C30 -> 1674 | M30: =+$M$2*$C30 -> 1674 | O30: =+$O$2*$C30 -> 1674 | Q30: =+$Q$2*$C30 -> 1674 | S30: =+$S$2*$C30 -> 1843.726
A31: 26 | B31: 602 | C31: 0.0281 | E31: =+$E$2*C31 -> 1665.7972 | F31: =+E31 -> 1665.7972 | G31: =+$G$2*C31 -> 1041.674 | I31: =+$I$2*C31 -> 1686 | K31: =+$K$2*$C31 -> 1686 | M31: =+$M$2*$C31 -> 1686 | O31: =+$O$2*$C31 -> 1686 | Q31: =+$Q$2*$C31 -> 1686 | S31: =+$S$2*$C31 -> 1856.9427
A32: 27 | B32: 603 | C32: 0.0244 | E32: =+$E$2*C32 -> 1446.4574 | G32: =+$G$2*C32 -> 904.5141 | I32: =+$I$2*C32 -> 1464 | K32: =+$K$2*$C32 -> 1464 | M32: =+$M$2*$C32 -> 1464 | O32: =+$O$2*$C32 -> 1464 | Q32: =+$Q$2*$C32 -> 1464 | S32: =+$S$2*$C32 -> 1612.4342
A33: 28 | B33: 604 | C33: 0.0194 | D33: 1974 | E33: =+$E$2*C33 -> 1150.0522 | G33: =+$G$2*C33 -> 719.16285 | I33: =+$I$2*C33 -> 1164 | K33: =+$K$2*$C33 -> 1164 | M33: =+$M$2*$C33 -> 1164 | N33: =+M33 -> 1164 | O33: =+$O$2*$C33 -> 1164 | P33: =+O33 -> 1164 | Q33: =+$Q$2*$C33 -> 1164 | S33: =+$S$2*$C33 -> 1282.0174
A34: 29 | B34: 701 | C34: 0.0279 | E34: =+$E$2*C34 -> 1653.941 | F34: =+E34 -> 1653.941 | G34: =+$G$2*C34 -> 1034.26 | I34: =+$I$2*C34 -> 1674 | K34: =+$K$2*$C34 -> 1674 | M34: =+$M$2*$C34 -> 1674 | O34: =+$O$2*$C34 -> 1674 | Q34: =+$Q$2*$C34 -> 1674 | S34: =+$S$2*$C34 -> 1843.726
A35: 30 | B35: 702 | C35: 0.0281 | E35: =+$E$2*C35 -> 1665.7972 | F35: =+E35 -> 1665.7972 | G35: =+$G$2*C35 -> 1041.674 | I35: =+$I$2*C35 -> 1686 | K35: =+$K$2*$C35 -> 1686 | M35: =+$M$2*$C35 -> 1686 | O35: =+$O$2*$C35 -> 1686 | Q35: =+$Q$2*$C35 -> 1686 | S35: =+$S$2*$C35 -> 1856.9427
A36: 31 | B36: 703 | C36: 0.0244 | E36: =+$E$2*C36 -> 1446.4574 | G36: =+$G$2*C36 -> 904.5141 | I36: =+$I$2*C36 -> 1464 | K36: =+$K$2*$C36 -> 1464 | M36: =+$M$2*$C36 -> 1464 | O36: =+$O$2*$C36 -> 1464 | Q36: =+$Q$2*$C36 -> 1464 | S36: =+$S$2*$C36 -> 1612.4342
A37: 32 | B37: 704 | C37: 0.0194 | D37: 940 | E37: =+$E$2*C37 -> 1150.0522 | F37: =+E37 -> 1150.0522 | G37: =+$G$2*C37 -> 719.16285 | I37: =+$I$2*C37 -> 1164 | J37: =+I37 -> 1164 | K37: =+$K$2*$C37 -> 1164 | M37: =+$M$2*$C37 -> 1164 | O37: =+$O$2*$C37 -> 1164 | Q37: =+$Q$2*$C37 -> 1164 | S37: =+$S$2*$C37 -> 1282.0174
A38: 33 | B38: 801 | C38: 0.0279 | D38: 2845 | E38: =+$E$2*C38 -> 1653.941 | F38: =+E38 -> 1653.941 | G38: =+$G$2*C38 -> 1034.26 | H38: =+G38+F38 -> 2688.201 | I38: =+$I$2*C38 -> 1674 | J38: =+H38+I38 -> 4362.201 | K38: =+$K$2*$C38 -> 1674 | L38: =+K38+J38 -> 6036.201 | M38: =+$M$2*$C38 -> 1674 | N38: =+M38+L38-F38 -> 6056.26 | O38: =+$O$2*$C38 -> 1674 | P38: =+O38+N38 -> 7730.26 | Q38: =+$Q$2*$C38 -> 1674 | S38: =+$S$2*$C38 -> 1843.726
A39: 34 | B39: 802 | C39: 0.0281 | E39: =+$E$2*C39 -> 1665.7972 | G39: =+$G$2*C39 -> 1041.674 | I39: =+$I$2*C39 -> 1686 | K39: =+$K$2*$C39 -> 1686 | M39: =+$M$2*$C39 -> 1686 | O39: =+$O$2*$C39 -> 1686 | Q39: =+$Q$2*$C39 -> 1686 | S39: =+$S$2*$C39 -> 1856.9427
A40: 35 | B40: 803 | C40: 0.0244 | E40: =+$E$2*C40 -> 1446.4574 | G40: =+$G$2*C40 -> 904.5141 | H40: =+G40 -> 904.5141 | I40: =+$I$2*C40 -> 1464 | K40: =+$K$2*$C40 -> 1464 | M40: =+$M$2*$C40 -> 1464 | O40: =+$O$2*$C40 -> 1464 | Q40: =+$Q$2*$C40 -> 1464 | S40: =+$S$2*$C40 -> 1612.4342
A41: 36 | B41: 804 | C41: 0.0194 | E41: =+$E$2*C41 -> 1150.0522 | F41: =+E41 -> 1150.0522 | G41: =+$G$2*C41 -> 719.16285 | I41: =+$I$2*C41 -> 1164 | J41: =+I41 -> 1164 | K41: =+$K$2*$C41 -> 1164 | M41: =+$M$2*$C41 -> 1164 | N41: =+M41 -> 1164 | O41: =+$O$2*$C41 -> 1164 | P41: =+O41 -> 1164 | Q41: =+$Q$2*$C41 -> 1164 | S41: =+$S$2*$C41 -> 1282.0174
...
